Workbook

Sheet raw enso data full
A1: Year | B1: ENSO | C1: IOD
A2: 1900 | B2: El Niño | C2: Neutral
A3: 1901 | B3: Neutral | C3: Positive
A4: 1902 | B4: Neutral | C4: Negative
A5: 1903 | B5: El Niño | C5: Negative
A6: 1904 | B6: La Niña | C6: Neutral
A7: 1905 | B7: Neutral | C7: Negative
A8: 1906 | B8: El Niño | C8: Neutral
A9: 1907 | B9: Neutral | C9: Positive
A10: 1908 | B10: Neutral | C10: Negative
A11: 1909 | B11: La Niña | C11: Neutral
A12: 1910 | B12: La Niña | C12: Positive
A13: 1911 | B13: La Niña | C13: Negative
... A125: 2023 | B125: El Niño | C125: Negative

Sheet ENSO
A1: El Niño
A2: 1900 | B2: El Niño | C2: Neutral | D2: El Niño IDO | E2: Positive | F2: 1919 | G2: 1931 | H2: 1958 | I2: 1973 | J2: 1980 | K2: 1983 | L2: 1992 | M2: 1995 | N2: 1998 | O2: 2007 | P2: 2010 | Q2: 2016
A3: 1903 | B3: El Niño | C3: Negative | E3: Negative | F3: 1903 | G3: 1926 | H3: 1941 | I3: 1978 | J3: 1987 | K3: 2023
A4: 1906 | B4: El Niño | C4: Neutral | E4: Neutral | F4: 1900 | G4: 1906 | H4: 1915 | I4: 1942 | J4: 1966 | K4: 1988 | L4: 2003 | M4: 2015
A5: 1915 | B5: El Niño | C5: Neutral
A6: 1919 | B6: El Niño | C6: Positive | D6: La Niña IDO | E6: Positive | F6: 1910 | G6: 1925 | H6: 1934 | I6: 1955 | J6: 1989 | K6: 2022
A7: 1926 | B7: El Niño | C7: Negative | E7: Negative | F7: 1911 | G7: 1917 | H7: 1950 | I7: 1956 | J7: 1962 | K7: 1971 | L7: 1974 | M7: 1999 | N7: 2008 | O7: 2011 | P7: 2017 | Q7: 2020
A8: 1931 | B8: El Niño | C8: Positive | E8: Neutral | F8: 1904 | G8: 1909 | H8: 1918 | I8: 1939 | J8: 1951 | K8: 1976 | L8: 2000 | M8: 2012 | N8: 2021
A9: 1941 | B9: El Niño | C9: Negative
A10: 1942 | B10: El Niño | C10: Neutral
A11: 1958 | B11: El Niño | C11: Positive | D11: Neutral IDO | E11: Positive | F11: 1901 | G11: 1907 | H11: 1913 | I11: 1916 | J11: 1922 | K11: 1928 | L11: 1937 | M11: 1940 | N11: 1946 | O11: 1949 | P11: 1952 | Q11: 1961 | R11: 1964 | S11: 1967 | T11: 1970 | U11: 1977 | V11: 1986 | W11: 2001 | X11: 2004 | Y11: 2013 | Z11: 2019
A12: 1966 | B12: El Niño | C12: Neutral | E12: Negative | F12: 1902 | G12: 1905 | H12: 1908 | I12: 1914 | J12: 1920 | K12: 1923 | L12: 1929 | M12: 1932 | N12: 1935 | O12: 1938 | P12: 1944 | Q12: 1947 | R12: 1953 | S12: 1959 | T12: 1965 | U12: 1968 | V12: 1981 | W12: 1984 | X12: 1990 | Y12: 1993 | Z12: 1996 | AA12: 2002 | AB12: 2005 | AC12: 2014
A13: 1973 | B13: El Niño | C13: Positive | E13: Neutral | F13: 1912 | G13: 1921 | H13: 1924 | I13: 1927 | J13: 1930 | K13: 1933 | L13: 1936 | M13: 1945 | N13: 1948 | O13: 1954 | P13: 1957 | Q13: 1960 | R13: 1963 | S13: 1969 | T13: 1972 | U13: 1975 | V13: 1979 | W13: 1982 | X13: 1985 | Y13: 1991 | Z13: 1994 | AA13: 1997 | AB13: 2006 | AC13: 2009 | AD13: 2018
A14: 1978 | B14: El Niño | C14: Negative
A15: 1980 | B15: El Niño | C15: Positive
A16: 1983 | B16: El Niño | C16: Positive
A17: 1987 | B17: El Niño | C17: Negative
A18: 1988 | B18: El Niño | C18: Neutral
A19: 1992 | B19: El Niño | C19: Positive
A20: 1995 | B20: El Niño | C20: Positive
A21: 1998 | B21: El Niño | C21: Positive
A22: 2003 | B22: El Niño | C22: Neutral
A23: 2007 | B23: El Niño | C23: Positive
A24: 2010 | B24: El Niño | C24: Positive
A25: 2015 | B25: El Niño | C25: Neutral
... A27: 2023 | B27: El Niño | C27: Negative
A30: La Niña
A31: 1904 | B31: La Niña | C31: Neutral | F31: Positive | G31: 1910 | H31: 1925 | I31: 1934 | J31: 1955 | K31: 1989 | L31: 2022
A32: 1909 | B32: La Niña | C32: Neutral | F32: Negative | G32: 1911 | H32: 1917 | I32: 1950 | J32: 1956 | K32: 1962 | L32: 1971 | M32: 1974 | N32: 1999 | O32: 2008 | P32: 2011 | Q32: 2017 | R32: 2020
A33: 1910 | B33: La Niña | C33: Positive | F33: Neutral | G33: 1904 | H33: 1909 | I33: 1918 | J33: 1939 | K33: 1951 | L33: 1976 | M33: 2000 | N33: 2012 | O33: 2021
A34: 1911 | B34: La Niña | C34: Negative
A35: 1917 | B35: La Niña | C35: Negative
A36: 1918 | B36: La Niña | C36: Neutral
A37: 1925 | B37: La Niña | C37: Positive
A38: 1934 | B38: La Niña | C38: Positive
A39: 1939 | B39: La Niña | C39: Neutral
A40: 1950 | B40: La Niña | C40: Negative
A41: 1951 | B41: La Niña | C41: Neutral
A42: 1955 | B42: La Niña | C42: Positive
A43: 1956 | B43: La Niña | C43: Negative
...

Sheet data convert
A1: Location
A2: Bangalore rural
A3: Year | B3: 1951 | C3: 1952 | D3: 1953 | E3: 1954 | F3: 1955 | G3: 1956 | H3: 1957 | I3: 1958 | J3: 1959 | K3: 1960 | L3: 1961 | M3: 1962 | N3: 1963 | O3: 1964 | P3: 1965 | Q3: 1966 | R3: 1967 | S3: 1968 | T3: 1969 | U3: 1970 | V3: 1971 | W3: 1972 | X3: 1973 | Y3: 1974 | Z3: 1975 | AA3: 1976 | AB3: 1977 | AC3: 1978 | AD3: 1979 | AE3: 1980 | AF3: 1981 | AG3: 1982 | AH3: 1983 | AI3: 1984 | AJ3: 1985 | AK3: 1986 | AL3: 1987 | AM3: 1988 | AN3: 1989 | AO3: 1990 | AP3: 1991 | AQ3: 1992 | AR3: 1993 | AS3: 1994 | AT3: 1995 | AU3: 1996 | AV3: 1997 | AW3: 1998 | AX3: 1999 | AY3: 2000 | AZ3: 2001 | BA3: 2002 | BB3: 2003 | BC3: 2004 | BD3: 2005 | BE3: 2006 | BF3: 2007 | BG3: 2008 | BH3: 2009 | BI3: 2010 | BJ3: 2011 | BK3: 2012 | BL3: 2013 | BM3: 2014 | BN3: 2015 | BO3: 2016 | BP3: 2017 | BQ3: 2018 | BR3: 2019 | BS3: 2020
A4: Jan | B4: 0 | C4: 0.95 | D4: 0 | E4: 3.1882353 | F4: 0.71333333 | G4: 0 | H4: 0 | I4: 7.20625 | J4: 0 | K4: 0 | L4: 6.2833333 | M4: 0 | N4: 0.84444444 | O4: 0 | P4: 0 | Q4: 0 | R4: 9.675 | S4: 0 | T4: 0 | U4: 0 | V4: 2.0851852 | W4: 0 | X4: 0 | Y4: 0 | Z4: 0 | AA4: 0 | AB4: 0 | AC4: 0 | AD4: 0.67 | AE4: 0 | AF4: 0.21621622 | AG4: 0 | AH4: 0 | AI4: 0.010810811 | AJ4: 1.5189189 | AK4: 15.727027 | AL4: 0.30810811 | AM4: 0 | AN4: 0 | AO4: 0.43428571 | AP4: 0.61818182 | AQ4: 0.13529412 | AR4: 0 | AS4: 3.9064516 | AT4: 1.0064516 | AU4: 0 | AV4: 3 | AW4: 0.14705882 | AX4: 0 | AY4: 0 | AZ4: 1.6107143 | BA4: 0 | BB4: 0 | BC4: 1.6645161 | BD4: 1.7758621 | BE4: 0 | BF4: 0 | BG4: 0 | BH4: 0 | BI4: 0 | BJ4: 0 | BK4: 0 | BL4: 0 | BM4: 0 | BN4: 2 | BO4: 5.05 | BP4: 1.76 | BQ4: 0 | BR4: 3.2 | BS4: 0.02
A5: Feb | B5: 0 | C5: 3.475 | D5: 2.65 | E5: 0 | F5: 0 | G5: 0 | H5: 0.038888889 | I5: 1.175 | J5: 2.9642857 | K5: 0 | L5: 6.3555556 | M5: 6.6222222 | N5: 0 | O5: 0 | P5: 0 | Q5: 0 | R5: 0 | S5: 3.425 | T5: 0 | U5: 15.492308 | V5: 13.737037 | W5: 0 | X5: 0 | Y5: 0 | Z5: 4.9857143 | AA5: 0 | AB5: 0.88974359 | AC5: 24.0925 | AD5: 75.75 | AE5: 0.125 | AF5: 0.24324324 | AG5: 0 | AH5: 0 | AI5: 13.57027 | AJ5: 0 | AK5: 11.043243 | AL5: 0 | AM5: 2.2222222 | AN5: 0 | AO5: 0 | AP5: 0.36969697 | AQ5: 0 | AR5: 0.55882353 | AS5: 10.796774 | AT5: 0.025806452 | AU5: 1 | AV5: 0 | AW5: 0 | AX5: 7.8794118 | AY5: 32.170968 | AZ5: 0 | BA5: 0 | BB5: 0.86875 | BC5: 1.4387097 | BD5: 6.7896552 | BE5: 0 | BF5: 1.3 | BG5: 2.1 | BH5: 0 | BI5: 0 | BJ5: 2.5 | BK5: 0 | BL5: 6.9 | BM5: 0.1 | BN5: 0 | BO5: 0.04 | BP5: 0 | BQ5: 4.02 | BR5: 26.32 | BS5: 0
A6: Mar | B6: 12.488235 | C6: 0 | D6: 0 | E6: 10.435294 | F6: 2.3066667 | G6: 0 | H6: 4.1333333 | I6: 16.7625 | J6: 0 | K6: 6.0294118 | L6: 1.5111111 | M6: 13.055556 | N6: 3.1055556 | O6: 0.508 | P6: 5.9 | Q6: 1.6642857 | R6: 12.9125 | S6: 0 | T6: 0.23888889 | U6: 1.5307692 | V6: 8.6407407 | W6: 0 | X6: 0.6 | Y6: 3.5628571 | Z6: 4.0771429 | AA6: 0.047368421 | AB6: 16.148718 | AC6: 2.385 | AD6: 0.7375 | AE6: 12.1725 | AF6: 17.237838 | AG6: 0.76315789 | AH6: 0.74444444 | AI6: 73.256757 | AJ6: 27.405405 | AK6: 0 | AL6: 16.016216 | AM6: 17.372222 | AN6: 10.131579 | AO6: 5.0085714 | AP6: 2.7545455 | AQ6: 0 | AR6: 8.8323529 | AS6: 0 | AT6: 1.6709677 | AU6: 2 | AV6: 32 | AW6: 1.4617647 | AX6: 2.0794118 | AY6: 0.25806452 | AZ6: 1.8392857 | BA6: 1.2481481 | BB6: 22.209375 | BC6: 7.5806452 | BD6: 6.6931034 | BE6: 62.7 | BF6: 0 | BG6: 100.9 | BH6: 17.3 | BI6: 18.5 | BJ6: 2.7 | BK6: 4.3 | BL6: 2.3 | BM6: 19.6 | BN6: 28 | BO6: 7.28 | BP6: 33.01 | BQ6: 26.65 | BR6: 0 | BS6: 12.63
A7: Apr | B7: 39.911765 | C7: 37.2 | D7: 89.55625 | E7: 17.358824 | F7: 57.006667 | G7: 16.377778 | H7: 13.616667 | I7: 36.11875 | J7: 10.328571 | K7: 12.905882 | L7: 29.166667 | M7: 106.69444 | N7: 58.455556 | O7: 12.464 | P7: 34.594118 | Q7: 27.414286 | R7: 13.075 | S7: 27.716667 | T7: 32.161111 | U7: 34.553846 | V7: 44.503704 | W7: 24.910714 | X7: 19.84 | Y7: 13.677143 | Z7: 10.171429 | AA7: 77.063158 | AB7: 49.151282 | AC7: 56.87 | AD7: 24.115 | AE7: 58.5425 | AF7: 37.016216 | AG7: 13.689474 | AH7: 8.1805556 | AI7: 25.824324 | AJ7: 42.891892 | AK7: 22.578378 | AL7: 9.9891892 | AM7: 94.780556 | AN7: 16.226316 | AO7: 12.871429 | AP7: 69.845455 | AQ7: 16.129412 | AR7: 16.494118 | AS7: 50.880645 | AT7: 32.693548 | AU7: 46 | AV7: 32 | AW7: 53.347059 | AX7: 68.047059 | AY7: 57.212903 | AZ7: 97.789286 | BA7: 11.166667 | BB7: 26.221875 | BC7: 63.887097 | BD7: 70.665517 | BE7: 11 | BF7: 46.3 | BG7: 15.2 | BH7: 11.7 | BI7: 42.4 | BJ7: 88.7 | BK7: 57.7 | BL7: 38.9 | BM7: 11 | BN7: 87 | BO7: 4.89 | BP7: 46.45 | BQ7: 17.39 | BR7: 44.76 | BS7: 77.61
A8: May | B8: 124.98235 | C8: 102.45 | D8: 45.50625 | E8: 139.95882 | F8: 77.753333 | G8: 34.572222 | H8: 139.90556 | I8: 126.24375 | J8: 74.228571 | K8: 46.535294 | L8: 84.261111 | M8: 86.816667 | N8: 53.777778 | O8: 60.724 | P8: 30.205882 | Q8: 130.22857 | R8: 79.55625 | S8: 82.066667 | T8: 114.11667 | U8: 148.48077 | V8: 143.6037 | W8: 173.44286 | X8: 82.997143 | Y8: 126.28857 | Z8: 129.72857 | AA8: 37.342105 | AB8: 159.52051 | AC8: 120.2025 | AD8: 65.915 | AE8: 156.135 | AF8: 133.44324 | AG8: 114.80526 | AH8: 107.08056 | AI8: 61.948649 | AJ8: 62.083784 | AK8: 72.205405 | AL8: 63.902703 | AM8: 123.14167 | AN8: 74.452632 | AO8: 116.90857 | AP8: 102.05152 | AQ8: 92.123529 | AR8: 69.891176 | AS8: 69.664516 | AT8: 77.73871 | AU8: 53 | AV8: 63 | AW8: 35.079412 | AX8: 141.38235 | AY8: 78.154839 | AZ8: 18.732143 | BA8: 108.77778 | BB8: 11.48125 | BC8: 197.99677 | BD8: 93.627586 | BE8: 72.5 | BF8: 76.6 | BG8: 100.7 | BH8: 92.4 | BI8: 114 | BJ8: 97.5 | BK8: 108.2 | BL8: 119.6 | BM8: 92.5 | BN8: 161 | BO8: 133.19 | BP8: 178.17 | BQ8: 135.1 | BR8: 114.69 | BS8: 80.89
A9: Jun | B9: 37.217647 | C9: 47.9 | D9: 79.15625 | E9: 34.311765 | F9: 49.673333 | G9: 77.744444 | H9: 77.35 | I9: 44.65625 | J9: 99.628571 | K9: 31.617647 | L9: 82.505556 | M9: 35.288889 | N9: 46.194444 | O9: 61.76 | P9: 34.305882 | Q9: 80.242857 | R9: 78.9875 | S9: 42.633333 | T9: 37.722222 | U9: 24.326923 | V9: 28.351852 | W9: 98.55 | X9: 46.168571 | Y9: 14.591429 | Z9: 70.2 | AA9: 24.418421 | AB9: 92.287179 | AC9: 50.845 | AD9: 127.5375 | AE9: 43.755 | AF9: 18.437838 | AG9: 92.571053 | AH9: 152.04722 | AI9: 33.794595 | AJ9: 57.018919 | AK9: 106.27838 | AL9: 87.148649 | AM9: 8.3194444 | AN9: 47.821053 | AO9: 39.217143 | AP9: 150.60909 | AQ9: 159.79706 | AR9: 115.40882 | AS9: 32.270968 | AT9: 63.332258 | AU9: 142 | AV9: 54 | AW9: 37.847059 | AX9: 41.811765 | AY9: 61.670968 | AZ9: 5.2 | BA9: 63.874074 | BB9: 51.796875 | BC9: 46.33871 | BD9: 46.772414 | BE9: 96.6 | BF9: 57.1 | BG9: 11.8 | BH9: 96.3 | BI9: 141.4 | BJ9: 47.4 | BK9: 20.4 | BL9: 81.5 | BM9: 61.4 | BN9: 67 | BO9: 151.53 | BP9: 42.01 | BQ9: 82.72 | BR9: 83.32 | BS9: 104.18
A10: Jul | B10: 129.09412 | C10: 85.4 | D10: 108.54375 | E10: 94.952941 | F10: 54.426667 | G10: 82.877778 | H10: 25.583333 | I10: 42.225 | J10: 26.392857 | K10: 83.317647 | L10: 73.061111 | M10: 37.144444 | N10: 75.35 | O10: 175.972 | P10: 26.082353 | Q10: 84.935714 | R10: 147.99375 | S10: 72.166667 | T10: 50.105556 | U10: 56.442308 | V10: 50.314815 | W10: 41.525 | X10: 75.922857 | Y10: 88.937143 | Z10: 224.71143 | AA10: 54.576316 | AB10: 84.207692 | AC10: 118.7075 | AD10: 75.545 | AE10: 72.43 | AF10: 74.562162 | AG10: 52.173684 | AH10: 74.202778 | AI10: 123.68378 | AJ10: 70.435135 | AK10: 46.351351 | AL10: 39.545946 | AM10: 194.41111 | AN10: 171.13421 | AO10: 29.374286 | AP10: 52.30303 | AQ10: 76.652941 | AR10: 72.797059 | AS10: 85.158065 | AT10: 95.596774 | AU10: 48 | AV10: 47 | AW10: 191.74412 | AX10: 43.714706 | AY10: 72.909677 | AZ10: 72.514286 | BA10: 29.396296 | BB10: 60.81875 | BC10: 199.56774 | BD10: 127.78966 | BE10: 37.2 | BF10: 100.8 | BG10: 149.1 | BH10: 30 | BI10: 145.6 | BJ10: 106.1 | BK10: 73.2 | BL10: 83.7 | BM10: 90.1 | BN10: 70 | BO10: 234.32 | BP10: 31.31 | BQ10: 36.16 | BR10: 49.38 | BS10: 219.32
A11: Aug | B11: 26.047059 | C11: 92.5 | D11: 21.05 | E11: 113.16471 | F11: 102.02 | G11: 57.783333 | H11: 34.333333 | I11: 130.40625 | J11: 118.65714 | K11: 74.082353 | L11: 87.105556 | M11: 141.27778 | N11: 135.82778 | O11: 93.38 | P11: 181.57059 | Q11: 75.578571 | R11: 49.0625 | S11: 31.091667 | T11: 211.24444 | U11: 82.526923 | V11: 202.46296 | W11: 66.225 | X11: 152.37714 | Y11: 49.871429 | Z11: 182.73143 | AA11: 96.021053 | AB11: 92.551282 | AC11: 76.7975 | AD11: 69.8625 | AE11: 63.0225 | AF11: 127.88108 | AG11: 31.302632 | AH11: 144.34167 | AI11: 23.578378 | AJ11: 54.278378 | AK11: 68.310811 | AL11: 82.081081 | AM11: 242.75 | AN11: 43.55 | AO11: 98.72 | AP11: 118.73636 | AQ11: 98.408824 | AR11: 138.57353 | AS11: 72.206452 | AT11: 162.70968 | AU11: 191 | AV11: 105 | AW11: 261.45882 | AX11: 95.435294 | AY11: 202.84194 | AZ11: 80.303571 | BA11: 22.240741 | BB11: 121.29375 | BC11: 38.729032 | BD11: 146.44828 | BE11: 31.1 | BF11: 133.6 | BG11: 223 | BH11: 101.5 | BI11: 148.4 | BJ11: 230.6 | BK11: 138.3 | BL11: 75.8 | BM11: 162.6 | BN11: 99 | BO11: 34.9 | BP11: 168.58 | BQ11: 55.56 | BR11: 95.77 | BS11: 89.51
A12: Sep | B12: 147.94118 | C12: 126.075 | D12: 114.975 | E12: 17.7 | F12: 121.69333 | G12: 109.83889 | H12: 43.033333 | I12: 135.38125 | J12: 236.37143 | K12: 178.42353 | L12: 96.466667 | M12: 179.92222 | N12: 182.56667 | O12: 236.644 | P12: 38.711765 | Q12: 210.22143 | R12: 79.95 | S12: 283.19167 | T12: 52.627778 | U12: 125.15 | V12: 169.01111 | W12: 206.81786 | X12: 258.24571 | Y12: 246.34571 | Z12: 264.83143 | AA12: 79.210526 | AB12: 144.46667 | AC12: 205.5925 | AD12: 246.01 | AE12: 144.4225 | AF12: 297.23243 | AG12: 169.91579 | AH12: 187.88333 | AI12: 169.24865 | AJ12: 131.13784 | AK12: 267.57297 | AL12: 162.37297 | AM12: 252.63056 | AN12: 183.62105 | AO12: 68.26 | AP12: 185.67273 | AQ12: 150.72941 | AR12: 190.88235 | AS12: 57.806452 | AT12: 98.43871 | AU12: 229 | AV12: 180 | AW12: 140.41176 | AX12: 142.92353 | AY12: 201.52581 | AZ12: 260.63214 | BA12: 59.825926 | BB12: 68.11875 | BC12: 170.86774 | BD12: 165.20345 | BE12: 45.6 | BF12: 166 | BG12: 103.9 | BH12: 258.1 | BI12: 108.9 | BJ12: 61.9 | BK12: 47.6 | BL12: 268.5 | BM12: 202.3 | BN12: 238 | BO12: 50.46 | BP12: 334.15 | BQ12: 101.82 | BR12: 142.75 | BS12: 180.54
A13: Oct | B13: 77.105882 | C13: 214.05 | D13: 295.4875 | E13: 167.42353 | F13: 143.62 | G13: 352.83889 | H13: 151.93889 | I13: 141.14375 | J13: 34.507143 | K13: 97.976471 | L13: 153.07222 | M13: 162.52778 | N13: 199.72778 | O13: 106.188 | P13: 22.847059 | Q13: 147.42143 | R13: 92.30625 | S13: 121.08333 | T13: 176.39444 | U13: 332.78462 | V13: 164.08519 | W13: 170.65 | X13: 258.82 | Y13: 186.23714 | Z13: 175.52 | AA13: 66.621053 | AB13: 243.81026 | AC13: 111.04 | AD13: 72.47 | AE13: 96.5325 | AF13: 170.30541 | AG13: 67.528947 | AH13: 65.230556 | AI13: 127.74865 | AJ13: 41.108108 | AK13: 78.178378 | AL13: 192.03514 | AM13: 34.861111 | AN13: 121.50526 | AO13: 108.09714 | AP13: 345.85455 | AQ13: 145.50588 | AR13: 222.53529 | AS13: 249.9 | AT13: 113.65161 | AU13: 133 | AV13: 176 | AW13: 153.54706 | AX13: 304.61765 | AY13: 327.39032 | AZ13: 139.91786 | BA13: 96.840741 | BB13: 152.63125 | BC13: 146.3 | BD13: 327.19655 | BE13: 75.6 | BF13: 184.2 | BG13: 150.4 | BH13: 23.2 | BI13: 86.1 | BJ13: 130.2 | BK13: 79.6 | BL13: 130.7 | BM13: 267.2 | BN13: 85 | BO13: 33.73 | BP13: 264.31 | BQ13: 81.16 | BR13: 219.46 | BS13: 194.64
A14: Nov | B14: 20.711765 | C14: 0 | D14: 1.8375 | E14: 0 | F14: 51.833333 | G14: 79.755556 | H14: 29.066667 | I14: 58.8125 | J14: 13.95 | K14: 66.7 | L14: 10.877778 | M14: 5.9777778 | N14: 13.488889 | O14: 136.692 | P14: 15.464706 | Q14: 167.97857 | R14: 46.46875 | S14: 21.125 | T14: 75.25 | U14: 22.992308 | V14: 19.959259 | W14: 27.139286 | X14: 29.454286 | Y14: 9.5428571 | Z14: 103.54286 | AA14: 112.32632 | AB14: 87.433333 | AC14: 65.8525 | AD14: 94.4925 | AE14: 66.7 | AF14: 48.47027 | AG14: 49.223684 | AH14: 9.4055556 | AI14: 5.0243243 | AJ14: 33.545946 | AK14: 90.786486 | AL14: 79.110811 | AM14: 8.1138889 | AN14: 7.0421053 | AO14: 36.605714 | AP14: 114.87273 | AQ14: 62.691176 | AR14: 41.411765 | AS14: 20.006452 | AT14: 23.141935 | AU14: 5 | AV14: 111 | AW14: 62.408824 | AX14: 66.455882 | AY14: 9.8322581 | AZ14: 33.160714 | BA14: 27.237037 | BB14: 9.190625 | BC14: 16.283871 | BD14: 90.893103 | BE14: 79.7 | BF14: 18.6 | BG14: 25.2 | BH14: 31.3 | BI14: 149.1 | BJ14: 26.7 | BK14: 106.8 | BL14: 59.8 | BM14: 35.4 | BN14: 243 | BO14: 7.76 | BP14: 26.32 | BQ14: 12.05 | BR14: 22.07 | BS14: 78.03
A15: Dec | B15: 0 | C15: 54.6625 | D15: 0 | E15: 18.058824 | F15: 3.1733333 | G15: 3.8388889 | H15: 0 | I15: 3.15625 | J15: 5.5357143 | K15: 0 | L15: 0.13888889 | M15: 52.011111 | N15: 10.883333 | O15: 3.48 | P15: 12.135294 | Q15: 6.5 | R15: 20.2125 | S15: 4.9083333 | T15: 50.888889 | U15: 0.088461538 | V15: 10.618519 | W15: 70.45 | X15: 15.865714 | Y15: 0 | Z15: 2.9485714 | AA15: 3.4631579 | AB15: 0.33076923 | AC15: 23.9825 | AD15: 0.9 | AE15: 0.525 | AF15: 11.118919 | AG15: 0.023684211 | AH15: 35.919444 | AI15: 1.7756757 | AJ15: 2.7189189 | AK15: 7.4351351 | AL15: 41.710811 | AM15: 18.258333 | AN15: 0.84736842 | AO15: 5.1571429 | AP15: 0 | AQ15: 0.43529412 | AR15: 43.291176 | AS15: 1.4903226 | AT15: 0 | AU15: 23 | AV15: 25 | AW15: 10.091176 | AX15: 6.95 | AY15: 4.6516129 | AZ15: 1.0142857 | BA15: 2 | BB15: 0 | BC15: 0 | BD15: 7.662069 | BE15: 1.7 | BF15: 20.3 | BG15: 2.3 | BH15: 20 | BI15: 11.2 | BJ15: 5.2 | BK15: 14.4 | BL15: 5.1 | BM15: 3.9 | BN15: 5 | BO15: 59.72 | BP15: 10.92 | BQ15: 7.28 | BR15: 14.06 | BS15: 19.92
A16: Annual
A17: winter
A18: summer
A19: SWMS
A20: NEMS
A22: Bangalore urban
A23: Year | B23: 1951 | C23: 1952 | D23: 1953 | E23: 1954 | F23: 1955 | G23: 1956 | H23: 1957 | I23: 1958 | J23: 1959 | K23: 1960 | L23: 1961 | M23: 1962 | N23: 1963 | O23: 1964 | P23: 1965 | Q23: 1966 | R23: 1967 | S23: 1968 | T23: 1969 | U23: 1970 | V23: 1971 | W23: 1972 | X23: 1973 | Y23: 1974 | Z23: 1975 | AA23: 1976 | AB23: 1977 | AC23: 1978 | AD23: 1979 | AE23: 1980 | AF23: 1981 | AG23: 1982 | AH23: 1983 | AI23: 1984 | AJ23: 1985 | AK23: 1986 | AL23: 1987 | AM23: 1988 | AN23: 1989 | AO23: 1990 | AP23: 1991 | AQ23: 1992 | AR23: 1993 | AS23: 1994 | AT23: 1995 | AU23: 1996 | AV23: 1997 | AW23: 1998 | AX23: 1999 | AY23: 2000 | AZ23: 2001 | BA23: 2002 | BB23: 2003 | BC23: 2004 | BD23: 2005 | BE23: 2006 | BF23: 2007 | BG23: 2008 | BH23: 2009 | BI23: 2010 | BJ23: 2011 | BK23: 2012 | BL23: 2013 | BM23: 2014 | BN23: 2015 | BO23: 2016 | BP23: 2017 | BQ23: 2018 | BR23: 2019 | BS23: 2020
A24: Jan | B24: 0 | C24: 0 | D24: 0 | E24: 3.28 | F24: 5.45 | G24: 1.2857143 | H24: 0.75454545 | I24: 5.4272727 | J24: 0 | K24: 0 | L24: 2.4444444 | M24: 0 | N24: 6.6888889 | O24: 0 | P24: 0 | Q24: 0 | R24: 9 | S24: 0 | T24: 0 | U24: 0 | V24: 0.038461538 | W24: 0.016666667 | X24: 0 | Y24: 0 | Z24: 0 | AA24: 0.22666667 | AB24: 0 | AC24: 0 | AD24: 0 | AE24: 0 | AF24: 0.50666667 | AG24: 0 | AH24: 0 | AI24: 1.3454545 | AJ24: 3.7416667 | AK24: 17.891667 | AL24: 0 | AM24: 0 | AN24: 0 | AO24: 0.95 | AP24: 0.31764706 | AQ24: 0 | AR24: 0 | AS24: 0.9 | AT24: 9.86875 | AU24: 0 | AV24: 1 | AW24: 0 | AX24: 0 | AY24: 0 | AZ24: 0.94285714 | BA24: 0.125 | BB24: 0 | BC24: 3.775 | BD24: 0.51111111 | BE24: 0.3 | BF24: 0 | BG24: 0.1 | BH24: 0.1 | BI24: 5.4 | BJ24: 0 | BK24: 0.1 | BL24: 0 | BM24: 0 | BN24: 8 | BO24: 7.25 | BP24: 0.5 | BQ24: 0 | BR24: 3.02 | BS24: 0.03
A25: Feb | B25: 0 | C25: 2.7 | D25: 0.9 | E25: 0 | F25: 0 | G25: 0 | H25: 0 | I25: 0.43636364 | J25: 21.225 | K25: 0 | L25: 13.088889 | M25: 1.8375 | N25: 0.22222222 | O25: 0 | P25: 0 | Q25: 0 | R25: 0 | S25: 1.9 | T25: 0 | U25: 23.341667 | V25: 0.53846154 | W25: 0 | X25: 0 | Y25: 0 | Z25: 3.8230769 | AA25: 0 | AB25: 1.3666667 | AC25: 10.670588 | AD25: 66.5375 | AE25: 0 | AF25: 0 | AG25: 0 | AH25: 0 | AI25: 24.518182 | AJ25: 0 | AK25: 19.733333 | AL25: 0 | AM25: 1.3866667 | AN25: 0 | AO25: 0 | AP25: 0 | AQ25: 0 | AR25: 0.28 | AS25: 7.69375 | AT25: 0 | AU25: 0 | AV25: 0 | AW25: 0 | AX25: 5.1066667 | AY25: 49.642857 | AZ25: 0 | BA25: 0 | BB25: 1.2 | BC25: 2.845 | BD25: 4.8388889 | BE25: 0 | BF25: 0.2 | BG25: 9.9 | BH25: 0 | BI25: 0 | BJ25: 18.2 | BK25: 0 | BL25: 4 | BM25: 0.1 | BN25: 0 | BO25: 0.07 | BP25: 0 | BQ25: 2.22 | BR25: 34.63 | BS25: 0
A26: Mar | B26: 2.2875 | C26: 0 | D26: 0 | E26: 0 | F26: 1.85 | G26: 0 | H26: 25.454545 | I26: 6.2181818 | J26: 0 | K26: 0.28888889 | L26: 0.52222222 | M26: 14.8125 | N26: 1.3777778 | O26: 0 | P26: 5.96 | Q26: 0 | R26: 7.1 | S26: 3 | T26: 1.2333333 | U26: 5.025 | V26: 12.107692 | W26: 0 | X26: 0 | Y26: 0 | Z26: 0.053846154 | AA26: 0 | AB26: 25.986667 | AC26: 1.4176471 | AD26: 0.075 | AE26: 15.58 | AF26: 31.046667 | AG26: 0.35714286 | AH26: 2.2923077 | AI26: 61.327273 | AJ26: 10.775 | AK26: 0 | AL26: 19.069231 | AM26: 22.02 | AN26: 8.8285714 | AO26: 7.5357143 | AP26: 1.7294118 | AQ26: 0 | AR26: 5.6 | AS26: 0.125 | AT26: 7.89375 | AU26: 0 | AV26: 34 | AW26: 2.2214286 | AX26: 0 | AY26: 0.25714286 | AZ26: 4.2285714 | BA26: 0.8375 | BB26: 10.473684 | BC26: 5.565 | BD26: 4.1777778 | BE26: 62.7 | BF26: 0 | BG26: 115.4 | BH26: 15.2 | BI26: 17.4 | BJ26: 2 | BK26: 0.6 | BL26: 2.6 | BM26: 12.9 | BN26: 29 | BO26: 8.91 | BP26: 33.81 | BQ26: 25.53 | BR26: 0 | BS26: 13.42
A27: Apr | B27: 11.6875 | C27: 4.275 | D27: 98.44 | E27: 13.82 | F27: 51.866667 | G27: 18.571429 | H27: 22.518182 | I27: 39.745455 | J27: 33.8 | K27: 2.8333333 | L27: 37.955556 | M27: 83.1375 | N27: 82.066667 | O27: 10.02 | P27: 26.98 | Q27: 30 | R27: 5.7714286 | S27: 15.75 | T27: 52 | U27: 45.316667 | V27: 43.792308 | W27: 21.75 | X27: 14.292308 | Y27: 11.233333 | Z27: 2.0615385 | AA27: 74.493333 | AB27: 46.586667 | AC27: 49.029412 | AD27: 18.8625 | AE27: 21.173333 | AF27: 31.186667 | AG27: 10.771429 | AH27: 6.9076923 | AI27: 22.090909 | AJ27: 24.65 | AK27: 4.9333333 | AL27: 25.284615 | AM27: 67.28 | AN27: 16.785714 | AO27: 14.764286 | AP27: 63.505882 | AQ27: 8.8857143 | AR27: 7.38 | AS27: 23.15 | AT27: 13.14375 | AU27: 72 | AV27: 40 | AW27: 51.964286 | AX27: 60.846667 | AY27: 46.092857 | AZ27: 159.66429 | BA27: 5.5 | BB27: 41.421053 | BC27: 49.825 | BD27: 68.266667 | BE27: 25.2 | BF27: 104.9 | BG27: 30.4 | BH27: 63.9 | BI27: 97.5 | BJ27: 157.8 | BK27: 21.1 | BL27: 28.9 | BM27: 7.2 | BN27: 115 | BO27: 7.74 | BP27: 42.05 | BQ27: 20.96 | BR27: 53.66 | BS27: 85.05
A28: May | B28: 109.2375 | C28: 60.65 | D28: 38.7 | E28: 150.16 | F28: 117.06667 | G28: 19.228571 | H28: 205.12727 | I28: 164.65455 | J28: 74.7 | K28: 51.244444 | L28: 91.211111 | M28: 88.175 | N28: 50.677778 | O28: 75.75 | P28: 18.08 | Q28: 107.98 | R28: 85.585714 | S28: 114.45 | T28: 154.8 | U28: 154.11667 | V28: 126.58462 | W28: 106.9 | X28: 74.969231 | Y28: 122.87333 | Z28: 110.57692 | AA28: 49.033333 | AB28: 139.27333 | AC28: 92.735294 | AD28: 60.1875 | AE28: 125.74 | AF28: 103.24 | AG28: 119.25 | AH28: 121.33077 | AI28: 42.581818 | AJ28: 44.108333 | AK28: 78 | AL28: 50.069231 | AM28: 92.82 | AN28: 67.107143 | AO28: 77.492857 | AP28: 119.04706 | AQ28: 109.54286 | AR28: 89.353333 | AS28: 66.59375 | AT28: 93.6 | AU28: 52 | AV28: 40 | AW28: 44.357143 | AX28: 174.51333 | AY28: 88.842857 | AZ28: 17.085714 | BA28: 141.9 | BB28: 3.4631579 | BC28: 210.665 | BD28: 101.61667 | BE28: 133.9 | BF28: 79.5 | BG28: 87.1 | BH28: 123.8 | BI28: 123.9 | BJ28: 139.1 | BK28: 108.1 | BL28: 110.1 | BM28: 83.2 | BN28: 131 | BO28: 132.82 | BP28: 205.68 | BQ28: 156.94 | BR28: 135.77 | BS28: 107.81
A29: Jun | B29: 27.0125 | C29: 71.975 | D29: 77.14 | E29: 53.98 | F29: 44.15 | G29: 60.385714 | H29: 80.245455 | I29: 58.036364 | J29: 98.9 | K29: 44.822222 | L29: 45.066667 | M29: 44.2 | N29: 56.455556 | O29: 59.27 | P29: 40.92 | Q29: 54.12 | R29: 97.271429 | S29: 90.85 | T29: 37.083333 | U29: 54.091667 | V29: 22.476923 | W29: 77.166667 | X29: 39.669231 | Y29: 9.22 | Z29: 62.230769 | AA29: 11.506667 | AB29: 100.48 | AC29: 30.3 | AD29: 118.1 | AE29: 31.52 | AF29: 12.986667 | AG29: 99.6 | AH29: 135.62308 | AI29: 36.454545 | AJ29: 49.708333 | AK29: 134.825 | AL29: 79.646154 | AM29: 11.513333 | AN29: 43.157143 | AO29: 35.8 | AP29: 155.72353 | AQ29: 146.61429 | AR29: 103.25333 | AS29: 33.40625 | AT29: 58.50625 | AU29: 159 | AV29: 42 | AW29: 45.107143 | AX29: 44.26 | AY29: 78.364286 | AZ29: 13.485714 | BA29: 94.78125 | BB29: 32.563158 | BC29: 57.705 | BD29: 54.988889 | BE29: 190.5 | BF29: 57.2 | BG29: 59.2 | BH29: 125.4 | BI29: 67.3 | BJ29: 54.5 | BK29: 9.2 | BL29: 93.1 | BM29: 93.7 | BN29: 90 | BO29: 153.65 | BP29: 30.96 | BQ29: 72.31 | BR29: 62.97 | BS29: 109.09
A30: Jul | B30: 104.75 | C30: 98.45 | D30: 125.16 | E30: 153.46 | F30: 58.616667 | G30: 95.985714 | H30: 20.436364 | I30: 49.581818 | J30: 30.9625 | K30: 63.455556 | L30: 60.255556 | M30: 34.25 | N30: 31.433333 | O30: 234.84 | P30: 35.44 | Q30: 126.72 | R30: 95.457143 | S30: 57.1 | T30: 70.816667 | U30: 62.591667 | V30: 52.730769 | W30: 32.708333 | X30: 76.623077 | Y30: 105.37333 | Z30: 175.81538 | AA30: 61.873333 | AB30: 99.073333 | AC30: 115.37647 | AD30: 92.08125 | AE30: 87.286667 | AF30: 67.593333 | AG30: 46.142857 | AH30: 42.507692 | AI30: 106.40909 | AJ30: 77.525 | AK30: 46.2 | AL30: 23.784615 | AM30: 175.40667 | AN30: 159.04286 | AO30: 24.414286 | AP30: 43.058824 | AQ30: 69.107143 | AR30: 57.633333 | AS30: 83.85625 | AT30: 74.21875 | AU30: 24 | AV30: 28 | AW30: 147.95714 | AX30: 73.953333 | AY30: 60.785714 | AZ30: 95.778571 | BA30: 34.81875 | BB30: 56.210526 | BC30: 179.67 | BD30: 102.12222 | BE30: 53.6 | BF30: 154 | BG30: 182.5 | BH30: 30.2 | BI30: 112.3 | BJ30: 92.6 | BK30: 63.7 | BL30: 76.2 | BM30: 80.6 | BN30: 53 | BO30: 212.86 | BP30: 29.02 | BQ30: 36.7 | BR30: 47.52 | BS30: 175.34
A31: Aug | B31: 24.275 | C31: 91.15 | D31: 29.1 | E31: 105.64 | F31: 106.48333 | G31: 53.414286 | H31: 42.545455 | I31: 222.57273 | J31: 171.625 | K31: 65.744444 | L31: 90.788889 | M31: 103.925 | N31: 165.62222 | O31: 94.51 | P31: 187.4 | Q31: 72.42 | R31: 29.7 | S31: 42.4 | T31: 196.65 | U31: 94.425 | V31: 259.13846 | W31: 121.7 | X31: 168.29231 | Y31: 73.106667 | Z31: 120.66923 | AA31: 140.53333 | AB31: 93.186667 | AC31: 87.029412 | AD31: 89.05 | AE31: 55.786667 | AF31: 112.30667 | AG31: 42.621429 | AH31: 160.66154 | AI31: 31.236364 | AJ31: 46.975 | AK31: 97.008333 | AL31: 90.138462 | AM31: 166.14667 | AN31: 39.742857 | AO31: 87.928571 | AP31: 110.86471 | AQ31: 92.407143 | AR31: 116.27333 | AS31: 52.6125 | AT31: 167.9 | AU31: 192 | AV31: 86 | AW31: 336.40714 | AX31: 108.60667 | AY31: 241.43571 | AZ31: 95.807143 | BA31: 27.48125 | BB31: 97.273684 | BC31: 58.87 | BD31: 153.55 | BE31: 44.2 | BF31: 146.5 | BG31: 247.4 | BH31: 162.2 | BI31: 121.1 | BJ31: 237.5 | BK31: 130.5 | BL31: 72.6 | BM31: 118.1 | BN31: 111 | BO31: 45.48 | BP31: 206.85 | BQ31: 72.78 | BR31: 102.55 | BS31: 67.92
A32: Sep | B32: 92.65 | C32: 89.95 | D32: 131.8 | E32: 16.74 | F32: 120.25 | G32: 194.42857 | H32: 37.881818 | I32: 165.78182 | J32: 160.85 | K32: 163.17778 | L32: 99.933333 | M32: 178.8 | N32: 179.24444 | O32: 230.49 | P32: 37.36 | Q32: 241.22 | R32: 46.142857 | S32: 308.05 | T32: 84.783333 | U32: 122.58333 | V32: 191.3 | W32: 258.26667 | X32: 221.4 | Y32: 241.7 | Z32: 138.36923 | AA32: 110.98 | AB32: 190.48667 | AC32: 174.18235 | AD32: 312.4875 | AE32: 142.80667 | AF32: 234.38 | AG32: 190.96429 | AH32: 194.00769 | AI32: 147.43636 | AJ32: 136.04167 | AK32: 351.64167 | AL32: 147.17692 | AM32: 236.94 | AN32: 178.42857 | AO32: 90.2 | AP32: 194.17059 | AQ32: 142.75 | AR32: 230.27333 | AS32: 84.79375 | AT32: 105.61875 | AU32: 207 | AV32: 215 | AW32: 195.63571 | AX32: 220.20667 | AY32: 179.48571 | AZ32: 259.52143 | BA32: 64.875 | BB32: 72.384211 | BC32: 193.365 | BD32: 194.09444 | BE32: 31.5 | BF32: 223.7 | BG32: 105.6 | BH32: 335.3 | BI32: 149.9 | BJ32: 89.3 | BK32: 41.3 | BL32: 249.3 | BM32: 181.8 | BN32: 194 | BO32: 41.91 | BP32: 400.97 | BQ32: 112.94 | BR32: 150.2 | BS32: 183.88
A33: Oct | B33: 56.05 | C33: 139.35 | D33: 318.74 | E33: 147.5 | F33: 128.46667 | G33: 483.02857 | H33: 181.47273 | I33: 104.3 | J33: 38.6125 | K33: 111.5 | L33: 142.03333 | M33: 186.075 | N33: 221.72222 | O33: 115.85 | P33: 3.46 | Q33: 123.24 | R33: 43.771429 | S33: 125.8 | T33: 209.76667 | U33: 243.60833 | V33: 133.92308 | W33: 286.88333 | X33: 227.46154 | Y33: 141.18 | Z33: 144.57692 | AA33: 95.2 | AB33: 257.4 | AC33: 79.888235 | AD33: 127.875 | AE33: 116.35333 | AF33: 115.30667 | AG33: 75.492857 | AH33: 57.176923 | AI33: 116.43636 | AJ33: 57.158333 | AK33: 52.475 | AL33: 168.73846 | AM33: 41.273333 | AN33: 149.99286 | AO33: 71.821429 | AP33: 335.41765 | AQ33: 119.95714 | AR33: 191.98667 | AS33: 190.71875 | AT33: 116.85625 | AU33: 68 | AV33: 170 | AW33: 212.38571 | AX33: 257.44667 | AY33: 200.30714 | AZ33: 119.66429 | BA33: 118.4125 | BB33: 184.41579 | BC33: 198.665 | BD33: 451.81111 | BE33: 48.9 | BF33: 163 | BG33: 210.9 | BH33: 35.2 | BI33: 95.8 | BJ33: 170.8 | BK33: 60 | BL33: 95.5 | BM33: 247.3 | BN33: 110 | BO33: 33.65 | BP33: 243.81 | BQ33: 80.68 | BR33: 224.26 | BS33: 213.95
A34: Nov | B34: 9.325 | C34: 0 | D34: 3.04 | E34: 0 | F34: 26.383333 | G34: 79.685714 | H34: 40.836364 | I34: 38.772727 | J34: 28.0375 | K34: 90.666667 | L34: 21.5 | M34: 5.25 | N34: 19.033333 | O34: 135.64 | P34: 29.46 | Q34: 232.12 | R34: 15.628571 | S34: 27.05 | T34: 104.61667 | U34: 34.933333 | V34: 22.207692 | W34: 42.016667 | X34: 39.607692 | Y34: 19.473333 | Z34: 117.60769 | AA34: 147.18667 | AB34: 93.86 | AC34: 33.852941 | AD34: 88.075 | AE34: 49.82 | AF34: 33.74 | AG34: 41.671429 | AH34: 2.4230769 | AI34: 10.045455 | AJ34: 50.566667 | AK34: 69.925 | AL34: 63.023077 | AM34: 15.313333 | AN34: 4.0785714 | AO34: 29.6 | AP34: 143.04706 | AQ34: 40.971429 | AR34: 38.02 | AS34: 24.06875 | AT34: 10.78125 | AU34: 2 | AV34: 129 | AW34: 46.685714 | AX34: 39.633333 | AY34: 3.2428571 | AZ34: 25.921429 | BA34: 35.6125 | BB34: 7.6894737 | BC34: 18.355 | BD34: 64.088889 | BE34: 48 | BF34: 21.1 | BG34: 47.6 | BH34: 66.8 | BI34: 166.8 | BJ34: 64.8 | BK34: 100.6 | BL34: 63.3 | BM34: 27.8 | BN34: 214 | BO34: 4.66 | BP34: 23.9 | BQ34: 9.98 | BR34: 29.86 | BS34: 80.63
A35: Dec | B35: 0 | C35: 51.325 | D35: 0 | E35: 14.66 | F35: 11.083333 | G35: 6.8 | H35: 0 | I35: 1.4636364 | J35: 5.7 | K35: 0.044444444 | L35: 0.77777778 | M35: 83.2625 | N35: 75.688889 | O35: 3.11 | P35: 36.2 | Q35: 10.86 | R35: 17.5 | S35: 12 | T35: 74.383333 | U35: 0.15 | V35: 9.3692308 | W35: 85.425 | X35: 18.315385 | Y35: 0.7 | Z35: 6.5538462 | AA35: 6.0466667 | AB35: 0 | AC35: 9.7294118 | AD35: 0 | AE35: 0.026666667 | AF35: 21.086667 | AG35: 0.12142857 | AH35: 42.538462 | AI35: 0.96363636 | AJ35: 3.175 | AK35: 9.925 | AL35: 27.1 | AM35: 20.206667 | AN35: 0.27142857 | AO35: 4.25 | AP35: 0 | AQ35: 0.042857143 | AR35: 56.093333 | AS35: 1.65625 | AT35: 0 | AU35: 11 | AV35: 14 | AW35: 9.1071429 | AX35: 13.12 | AY35: 4.4857143 | AZ35: 4.15 | BA35: 1.5875 | BB35: 0.18947368 | BC35: 0 | BD35: 6.7944444 | BE35: 0.3 | BF35: 34.5 | BG35: 0.3 | BH35: 17.5 | BI35: 2.7 | BJ35: 5.9 | BK35: 17.2 | BL35: 1.4 | BM35: 2 | BN35: 3 | BO35: 67.98 | BP35: 15.93 | BQ35: 8.02 | BR35: 15.91 | BS35: 19.51
A36: Annual
A37: winter
A38: summer
A39: SWMS
A40: NEMS
A42: Kolar
...

Sheet Data
A1: ='data convert'!A1 -> Location | CN1: % Dev with Normal RF | DD1: % Dev with there event
A2: ='data convert'!A2 -> Bangalore rural | BV2: =B2 -> 0 | BX2: Normal RF of events | CB2: El Niño | CF2: La Niña | CJ2: Neutral | CR2: El Niño | CV2: La Niña | CZ2: Neutral | DE2: Normal copyed | DH2: El Niño | DL2: La Niña | DP2: Neutral
A3: ='data convert'!A3 -> Year | B3: 1951 | C3: 1952 | D3: 1953 | E3: 1954 | F3: 1955 | G3: 1956 | H3: 1957 | I3: 1958 | J3: 1959 | K3: 1960 | L3: 1961 | M3: 1962 | N3: 1963 | O3: 1964 | P3: 1965 | Q3: 1966 | R3: 1967 | S3: 1968 | T3: 1969 | U3: 1970 | V3: 1971 | W3: 1972 | X3: 1973 | Y3: 1974 | Z3: 1975 | AA3: 1976 | AB3: 1977 | AC3: 1978 | AD3: 1979 | AE3: 1980 | AF3: 1981 | AG3: 1982 | AH3: 1983 | AI3: 1984 | AJ3: 1985 | AK3: 1986 | AL3: 1987 | AM3: 1988 | AN3: 1989 | AO3: 1990 | AP3: 1991 | AQ3: 1992 | AR3: 1993 | AS3: 1994 | AT3: 1995 | AU3: 1996 | AV3: 1997 | AW3: 1998 | AX3: 1999 | AY3: 2000 | AZ3: 2001 | BA3: 2002 | BB3: 2003 | BC3: 2004 | BD3: 2005 | BE3: 2006 | BF3: 2007 | BG3: 2008 | BH3: 2009 | BI3: 2010 | BJ3: 2011 | BK3: 2012 | BL3: 2013 | BM3: 2014 | BN3: 2015 | BO3: 2016 | BP3: 2017 | BQ3: 2018 | BR3: 2019 | BS3: 2020 | BV3: Normal | BX3: El Niño | BY3: La Niña | BZ3: Neutral | CB3: el PIOD | CC3: el NIOD | CD3: el NUIOD | CF3: la PIOD | CG3: la NIOD | CH3: la NUIOD | CJ3: Nu PIOD | CK3: Nu NIOD | CL3: Nu NUIOD | CN3: El Niño | CO3: La Niña | CP3: Neutral | CR3: el PIOD | CS3: el NIOD | CT3: el NUIOD | CV3: la PIOD | CW3: la NIOD | CX3: la NUIOD | CZ3: Nu PIOD | DA3: Nu NIOD | DB3: Nu NUIOD | DD3: El Niño | DE3: La Niña | DF3: Neutral | DH3: el PIOD | DI3: el NIOD | DJ3: el NUIOD | DL3: la PIOD | DM3: la NIOD | DN3: la NUIOD | DP3: Nu PIOD | DQ3: Nu NIOD | DR3: Nu NUIOD
A4: ='data convert'!A4 -> Jan | B4: ='data convert'!B4 -> 0 | C4: ='data convert'!C4 -> 0.95 | D4: ='data convert'!D4 -> 0 | E4: ='data convert'!E4 -> 3.1882353 | F4: ='data convert'!F4 -> 0.71333333 | G4: ='data convert'!G4 -> 0 | H4: ='data convert'!H4 -> 0 | ... BS4: ='data convert'!BS4 -> 0.02 | BV4: =AVERAGE(B4:BS4) -> 1.0817954 | BX4: =AVERAGE(I4,Q4,X4,AC4,AE4,AH4,AL4,AM4,AQ4,AT4,AW4,BB4,BF4,BI4,BN4,BO4) -> 0.99082267 | BY4: =AVERAGE(B4,F4,G4,M4,V4,Y4,AA4,AN4,AX4,AY4,BG4,BJ4,BK4,BP4,BS4) -> 0.30523457 | BZ4: =AVERAGE(C4,D4,E4,H4,K4,L4,N4,O4,P4,R4,S4,T4,U4,W4,Z4,AB4,AD4,AF4,AG4,AI4,AJ4,AK4,AO4,AP4,AR4,AS4,AU4,AV4,AZ4,BA4,BC4,BD4,BE4,BH4,BL4,BM4,BQ4,BR4) -> 1.4551052 | CB4: =AVERAGE(I4,X4,AE4,AH4,AQ4,AT4,AW4,BF4,BI4,BO4) -> 1.3545055 | CC4: =AVERAGE(AC4,AL4) -> 0.15405405 | CD4: =AVERAGE(Q4,AM4,BB4,BN4) -> 0.5 | CF4: =AVERAGE(F4,AN4) -> 0.35666667 | CG4: =AVERAGE(G4,M4,V4,Y4,AX4,BG4,BJ4,BP4,BS4) -> 0.42946502 | CH4: =AVERAGE(AA4,AY4,BK4) -> 0 | CJ4: =AVERAGE(C4,L4,O4,R4,AB4,AK4,AZ4,BC4,BL4,BR4) -> 3.9110591 | CK4: =AVERAGE(D4,J4,P4,S4,AF4,AI4,AO4,AR4,AU4,BA4,BD4,BM4) -> 0.2030979 | CL4: =AVERAGE(E4,H4,K4,N4,T4,W4,Z4,AD4,AG4,AJ4,AP4,AS4,AV4,BE4,BH4,BQ4) -> 0.85913951 | CN4: =(BX4-$BV4)/$BV4*100 -> -8.4094224 | CO4: =(BY4-$BV4)/$BV4*100 -> -71.784446 | CP4: =(BZ4-$BV4)/$BV4*100 -> 34.508354 | CR4: =(CB4-$BV4)/$BV4*100 -> 25.209022 | CS4: =(CC4-$BV4)/$BV4*100 -> -85.75941 | CT4: =(CD4-$BV4)/$BV4*100 -> -53.78054 | CV4: =(CF4-$BV4)/$BV4*100 -> -67.030118 | CW4: =(CG4-$BV4)/$BV4*100 -> -60.300717 | CX4: =(CH4-$BV4)/$BV4*100 -> -100 | CZ4: =(CJ4-$BV4)/$BV4*100 -> 261.53408 | DA4: =(CK4-$BV4)/$BV4*100 -> -81.225849 | DB4: =(CL4-$BV4)/$BV4*100 -> -20.582072 | DD4: =BX4 -> 0.99082267 | DE4: =BY4 -> 0.30523457 | DF4: =BZ4 -> 1.4551052 | DH4: =(CB4-$DD4)/$DD4*100 -> 36.705134 | DI4: =(CC4-$DD4)/$DD4*100 -> -84.451905 | DJ4: =(CD4-$DD4)/$DD4*100 -> -49.536883 | DL4: =(CF4-$DE4)/$DE4*100 -> 16.850024 | DM4: =(CG4-$DE4)/$DE4*100 -> 40.699995 | DN4: =(CH4-$DE4)/$DE4*100 -> -100 | DP4: =(CJ4-$DF4)/$DF4*100 -> 168.78188 | DQ4: =(CK4-$DF4)/$DF4*100 -> -86.042391 | DR4: =(CL4-$DF4)/$DF4*100 -> -40.95688
A5: ='data convert'!A5 -> Feb | B5: ='data convert'!B5 -> 0 | C5: ='data convert'!C5 -> 3.475 | D5: ='data convert'!D5 -> 2.65 | E5: ='data convert'!E5 -> 0 | F5: ='data convert'!F5 -> 0 | G5: ='data convert'!G5 -> 0 | H5: ='data convert'!H5 -> 0.038888889 | ... BS5: ='data convert'!BS5 -> 0 | BV5: =AVERAGE(B5:BS5) -> 4.2005118 | BX5: =AVERAGE(I5,Q5,X5,AC5,AE5,AH5,AL5,AM5,AQ5,AT5,AW5,BB5,BF5,BI5,BN5,BO5) -> 1.8655799 | BY5: =AVERAGE(B5,F5,G5,M5,V5,Y5,AA5,AN5,AX5,AY5,BG5,BJ5,BK5,BP5,BS5) -> 4.3339759 | BZ5: =AVERAGE(C5,D5,E5,H5,K5,L5,N5,O5,P5,R5,S5,T5,U5,W5,Z5,AB5,AD5,AF5,AG5,AI5,AJ5,AK5,AO5,AP5,AR5,AS5,AU5,AV5,AZ5,BA5,BC5,BD5,BE5,BH5,BL5,BM5,BQ5,BR5) -> 5.1634902 | CB5: =AVERAGE(I5,X5,AE5,AH5,AQ5,AT5,AW5,BF5,BI5,BO5) -> 0.26658065 | CC5: =AVERAGE(AC5,AL5) -> 12.04625 | CD5: =AVERAGE(Q5,AM5,BB5,BN5) -> 0.77274306 | CF5: =AVERAGE(F5,AN5) -> 0 | CG5: =AVERAGE(G5,M5,V5,Y5,AX5,BG5,BJ5,BP5,BS5) -> 3.6487412 | CH5: =AVERAGE(AA5,AY5,BK5) -> 10.723656 | CJ5: =AVERAGE(C5,L5,O5,R5,AB5,AK5,AZ5,BC5,BL5,BR5) -> 5.6422252 | CK5: =AVERAGE(D5,J5,P5,S5,AF5,AI5,AO5,AR5,AU5,BA5,BD5,BM5) -> 2.6084398 | CL5: =AVERAGE(E5,H5,K5,N5,T5,W5,Z5,AD5,AG5,AJ5,AP5,AS5,AV5,BE5,BH5,BQ5) -> 5.9975671 | CN5: =(BX5-$BV5)/$BV5*100 -> -55.586843 | CO5: =(BY5-$BV5)/$BV5*100 -> 3.1773287 | CP5: =(BZ5-$BV5)/$BV5*100 -> 22.925261 | CR5: =(CB5-$BV5)/$BV5*100 -> -93.653615 | CS5: =(CC5-$BV5)/$BV5*100 -> 186.78053 | CT5: =(CD5-$BV5)/$BV5*100 -> -81.603598 | CV5: =(CF5-$BV5)/$BV5*100 -> -100 | CW5: =(CG5-$BV5)/$BV5*100 -> -13.135795 | CX5: =(CH5-$BV5)/$BV5*100 -> 155.29403 | CZ5: =(CJ5-$BV5)/$BV5*100 -> 34.322326 | DA5: =(CK5-$BV5)/$BV5*100 -> -37.901858 | DB5: =(CL5-$BV5)/$BV5*100 -> 42.781817 | DD5: =BX5 -> 1.8655799 | DE5: =BY5 -> 4.3339759 | DF5: =BZ5 -> 5.1634902 | DH5: =(CB5-$DD5)/$DD5*100 -> -85.710575 | DI5: =(CC5-$DD5)/$DD5*100 -> 545.71075 | DJ5: =(CD5-$DD5)/$DD5*100 -> -58.578936 | DL5: =(CF5-$DE5)/$DE5*100 -> -100 | DM5: =(CG5-$DE5)/$DE5*100 -> -15.810764 | DN5: =(CH5-$DE5)/$DE5*100 -> 147.43229 | DP5: =(CJ5-$DF5)/$DF5*100 -> 9.2715397 | DQ5: =(CK5-$DF5)/$DF5*100 -> -49.48301 | DR5: =(CL5-$DF5)/$DF5*100 -> 16.153357
A6: ='data convert'!A6 -> Mar | B6: ='data convert'!B6 -> 12.488235 | C6: ='data convert'!C6 -> 0 | D6: ='data convert'!D6 -> 0 | E6: ='data convert'!E6 -> 10.435294 | F6: ='data convert'!F6 -> 2.3066667 | G6: ='data convert'!G6 -> 0 | H6: ='data convert'!H6 -> 4.1333333 | ... BS6: ='data convert'!BS6 -> 12.63 | BV6: =AVERAGE(B6:BS6) -> 10.50554 | BX6: =AVERAGE(I6,Q6,X6,AC6,AE6,AH6,AL6,AM6,AQ6,AT6,AW6,BB6,BF6,BI6,BN6,BO6) -> 9.1774548 | BY6: =AVERAGE(B6,F6,G6,M6,V6,Y6,AA6,AN6,AX6,AY6,BG6,BJ6,BK6,BP6,BS6) -> 13.740699 | BZ6: =AVERAGE(C6,D6,E6,H6,K6,L6,N6,O6,P6,R6,S6,T6,U6,W6,Z6,AB6,AD6,AF6,AG6,AI6,AJ6,AK6,AO6,AP6,AR6,AS6,AU6,AV6,AZ6,BA6,BC6,BD6,BE6,BH6,BL6,BM6,BQ6,BR6) -> 10.064159 | CB6: =AVERAGE(I6,X6,AE6,AH6,AQ6,AT6,AW6,BF6,BI6,BO6) -> 5.9192177 | CC6: =AVERAGE(AC6,AL6) -> 9.2006081 | CD6: =AVERAGE(Q6,AM6,BB6,BN6) -> 17.311471 | CF6: =AVERAGE(F6,AN6) -> 6.2191228 | CG6: =AVERAGE(G6,M6,V6,Y6,AX6,BG6,BJ6,BP6,BS6) -> 19.619841 | CH6: =AVERAGE(AA6,AY6,BK6) -> 1.5351443 | CJ6: =AVERAGE(C6,L6,O6,R6,AB6,AK6,AZ6,BC6,BL6,BR6) -> 4.280026 | CK6: =AVERAGE(D6,J6,P6,S6,AF6,AI6,AO6,AR6,AU6,BA6,BD6,BM6) -> 11.648064 | CL6: =AVERAGE(E6,H6,K6,N6,T6,W6,Z6,AD6,AG6,AJ6,AP6,AS6,AV6,BE6,BH6,BQ6) -> 12.39564 | CN6: =(BX6-$BV6)/$BV6*100 -> -12.64176 | CO6: =(BY6-$BV6)/$BV6*100 -> 30.794788 | CP6: =(BZ6-$BV6)/$BV6*100 -> -4.2014123 | CR6: =(CB6-$BV6)/$BV6*100 -> -43.656225 | CS6: =(CC6-$BV6)/$BV6*100 -> -12.421368 | CT6: =(CD6-$BV6)/$BV6*100 -> 64.784209 | CV6: =(CF6-$BV6)/$BV6*100 -> -40.801492 | CW6: =(CG6-$BV6)/$BV6*100 -> 86.75709 | CX6: =(CH6-$BV6)/$BV6*100 -> -85.387288 | CZ6: =(CJ6-$BV6)/$BV6*100 -> -59.259343 | DA6: =(CK6-$BV6)/$BV6*100 -> 10.875446 | DB6: =(CL6-$BV6)/$BV6*100 -> 17.991459 | DD6: =BX6 -> 9.1774548 | DE6: =BY6 -> 13.740699 | DF6: =BZ6 -> 10.064159 | DH6: =(CB6-$DD6)/$DD6*100 -> -35.502622 | DI6: =(CC6-$DD6)/$DD6*100 -> 0.25228515 | DJ6: =(CD6-$DD6)/$DD6*100 -> 88.630412 | DL6: =(CF6-$DE6)/$DE6*100 -> -54.739399 | DM6: =(CG6-$DE6)/$DE6*100 -> 42.78634 | DN6: =(CH6-$DE6)/$DE6*100 -> -88.827756 | DP6: =(CJ6-$DF6)/$DF6*100 -> -57.472591 | DQ6: =(CK6-$DF6)/$DF6*100 -> 15.73808 | DR6: =(CL6-$DF6)/$DF6*100 -> 23.166177
A7: ='data convert'!A7 -> Apr | B7: ='data convert'!B7 -> 39.911765 | C7: ='data convert'!C7 -> 37.2 | D7: ='data convert'!D7 -> 89.55625 | E7: ='data convert'!E7 -> 17.358824 | F7: ='data convert'!F7 -> 57.006667 | G7: ='data convert'!G7 -> 16.377778 | H7: ='data convert'!H7 -> 13.616667 | ... BS7: ='data convert'!BS7 -> 77.61 | BV7: =AVERAGE(B7:BS7) -> 38.327868 | BX7: =AVERAGE(I7,Q7,X7,AC7,AE7,AH7,AL7,AM7,AQ7,AT7,AW7,BB7,BF7,BI7,BN7,BO7) -> 38.794858 | BY7: =AVERAGE(B7,F7,G7,M7,V7,Y7,AA7,AN7,AX7,AY7,BG7,BJ7,BK7,BP7,BS7) -> 52.158729 | BZ7: =AVERAGE(C7,D7,E7,H7,K7,L7,N7,O7,P7,R7,S7,T7,U7,W7,Z7,AB7,AD7,AF7,AG7,AI7,AJ7,AK7,AO7,AP7,AR7,AS7,AU7,AV7,AZ7,BA7,BC7,BD7,BE7,BH7,BL7,BM7,BQ7,BR7) -> 33.408513 | CB7: =AVERAGE(I7,X7,AE7,AH7,AQ7,AT7,AW7,BF7,BI7,BO7) -> 31.844182 | CC7: =AVERAGE(AC7,AL7) -> 33.429595 | CD7: =AVERAGE(Q7,AM7,BB7,BN7) -> 58.854179 | CF7: =AVERAGE(F7,AN7) -> 36.616491 | CG7: =AVERAGE(G7,M7,V7,Y7,AX7,BG7,BJ7,BP7,BS7) -> 53.028903 | CH7: =AVERAGE(AA7,AY7,BK7) -> 63.99202 | CJ7: =AVERAGE(C7,L7,O7,R7,AB7,AK7,AZ7,BC7,BL7,BR7) -> 40.897171 | CK7: =AVERAGE(D7,J7,P7,S7,AF7,AI7,AO7,AR7,AU7,BA7,BD7,BM7) -> 32.76949 | CL7: =AVERAGE(E7,H7,K7,N7,T7,W7,Z7,AD7,AG7,AJ7,AP7,AS7,AV7,BE7,BH7,BQ7) -> 27.69329 | CN7: =(BX7-$BV7)/$BV7*100 -> 1.2184094 | CO7: =(BY7-$BV7)/$BV7*100 -> 36.085653 | CP7: =(BZ7-$BV7)/$BV7*100 -> -12.834928 | CR7: =(CB7-$BV7)/$BV7*100 -> -16.916374 | CS7: =(CC7-$BV7)/$BV7*100 -> -12.779926 | CT7: =(CD7-$BV7)/$BV7*100 -> 53.554535 | CV7: =(CF7-$BV7)/$BV7*100 -> -4.4650972 | CW7: =(CG7-$BV7)/$BV7*100 -> 38.355996 | CX7: =(CH7-$BV7)/$BV7*100 -> 66.95951 | CZ7: =(CJ7-$BV7)/$BV7*100 -> 6.7034858 | DA7: =(CK7-$BV7)/$BV7*100 -> -14.502184 | DB7: =(CL7-$BV7)/$BV7*100 -> -27.746332 | DD7: =BX7 -> 38.794858 | DE7: =BY7 -> 52.158729 | DF7: =BZ7 -> 33.408513 | DH7: =(CB7-$DD7)/$DD7*100 -> -17.916487 | DI7: =(CC7-$DD7)/$DD7*100 -> -13.829832 | DJ7: =(CD7-$DD7)/$DD7*100 -> 51.706133 | DL7: =(CF7-$DE7)/$DE7*100 -> -29.797961 | DM7: =(CG7-$DE7)/$DE7*100 -> 1.668319 | DN7: =(CH7-$DE7)/$DE7*100 -> 22.687078 | DP7: =(CJ7-$DF7)/$DF7*100 -> 22.415417 | DQ7: =(CK7-$DF7)/$DF7*100 -> -1.912757 | DR7: =(CL7-$DF7)/$DF7*100 -> -17.107085
A8: ='data convert'!A8 -> May | B8: ='data convert'!B8 -> 124.98235 | C8: ='data convert'!C8 -> 102.45 | D8: ='data convert'!D8 -> 45.50625 | E8: ='data convert'!E8 -> 139.95882 | F8: ='data convert'!F8 -> 77.753333 | G8: ='data convert'!G8 -> 34.572222 | H8: ='data convert'!H8 -> 139.90556 | ... BS8: ='data convert'!BS8 -> 80.89 | BV8: =AVERAGE(B8:BS8) -> 97.103722 | BX8: =AVERAGE(I8,Q8,X8,AC8,AE8,AH8,AL8,AM8,AQ8,AT8,AW8,BB8,BF8,BI8,BN8,BO8) -> 100.69655 | BY8: =AVERAGE(B8,F8,G8,M8,V8,Y8,AA8,AN8,AX8,AY8,BG8,BJ8,BK8,BP8,BS8) -> 99.387252 | BZ8: =AVERAGE(C8,D8,E8,H8,K8,L8,N8,O8,P8,R8,S8,T8,U8,W8,Z8,AB8,AD8,AF8,AG8,AI8,AJ8,AK8,AO8,AP8,AR8,AS8,AU8,AV8,AZ8,BA8,BC8,BD8,BE8,BH8,BL8,BM8,BQ8,BR8) -> 95.291537 | CB8: =AVERAGE(I8,X8,AE8,AH8,AQ8,AT8,AW8,BF8,BI8,BO8) -> 100.11881 | CC8: =AVERAGE(AC8,AL8) -> 92.052601 | CD8: =AVERAGE(Q8,AM8,BB8,BN8) -> 106.46287 | CF8: =AVERAGE(F8,AN8) -> 76.102982 | CG8: =AVERAGE(G8,M8,V8,Y8,AX8,BG8,BJ8,BP8,BS8) -> 109.9915 | CH8: =AVERAGE(AA8,AY8,BK8) -> 74.565648 | CJ8: =AVERAGE(C8,L8,O8,R8,AB8,AK8,AZ8,BC8,BL8,BR8) -> 100.97362 | CK8: =AVERAGE(D8,J8,P8,S8,AF8,AI8,AO8,AR8,AU8,BA8,BD8,BM8) -> 80.175365 | CL8: =AVERAGE(E8,H8,K8,N8,T8,W8,Z8,AD8,AG8,AJ8,AP8,AS8,AV8,BE8,BH8,BQ8) -> 98.436602 | CN8: =(BX8-$BV8)/$BV8*100 -> 3.6999895 | CO8: =(BY8-$BV8)/$BV8*100 -> 2.3516401 | CP8: =(BZ8-$BV8)/$BV8*100 -> -1.8662367 | CR8: =(CB8-$BV8)/$BV8*100 -> 3.105018 | CS8: =(CC8-$BV8)/$BV8*100 -> -5.2017785 | CT8: =(CD8-$BV8)/$BV8*100 -> 9.6383022 | CV8: =(CF8-$BV8)/$BV8*100 -> -21.627121 | CW8: =(CG8-$BV8)/$BV8*100 -> 13.272179 | CX8: =(CH8-$BV8)/$BV8*100 -> -23.210309 | CZ8: =(CJ8-$BV8)/$BV8*100 -> 3.9853238 | DA8: =(CK8-$BV8)/$BV8*100 -> -17.433273 | DB8: =(CL8-$BV8)/$BV8*100 -> 1.372635 | DD8: =BX8 -> 100.69655 | DE8: =BY8 -> 99.387252 | DF8: =BZ8 -> 95.291537 | DH8: =(CB8-$DD8)/$DD8*100 -> -0.57374305 | DI8: =(CC8-$DD8)/$DD8*100 -> -8.5841551 | DJ8: =(CD8-$DD8)/$DD8*100 -> 5.7264352 | DL8: =(CF8-$DE8)/$DE8*100 -> -23.427823 | DM8: =(CG8-$DE8)/$DE8*100 -> 10.669628 | DN8: =(CH8-$DE8)/$DE8*100 -> -24.974636 | DP8: =(CJ8-$DF8)/$DF8*100 -> 5.9628412 | DQ8: =(CK8-$DF8)/$DF8*100 -> -15.863079 | DR8: =(CL8-$DF8)/$DF8*100 -> 3.3004661
A9: ='data convert'!A9 -> Jun | B9: ='data convert'!B9 -> 37.217647 | C9: ='data convert'!C9 -> 47.9 | D9: ='data convert'!D9 -> 79.15625 | E9: ='data convert'!E9 -> 34.311765 | F9: ='data convert'!F9 -> 49.673333 | G9: ='data convert'!G9 -> 77.744444 | H9: ='data convert'!H9 -> 77.35 | ... BS9: ='data convert'!BS9 -> 104.18 | BV9: =AVERAGE(B9:BS9) -> 65.142469 | BX9: =AVERAGE(I9,Q9,X9,AC9,AE9,AH9,AL9,AM9,AQ9,AT9,AW9,BB9,BF9,BI9,BN9,BO9) -> 77.68664 | BY9: =AVERAGE(B9,F9,G9,M9,V9,Y9,AA9,AN9,AX9,AY9,BG9,BJ9,BK9,BP9,BS9) -> 42.958653 | BZ9: =AVERAGE(C9,D9,E9,H9,K9,L9,N9,O9,P9,R9,S9,T9,U9,W9,Z9,AB9,AD9,AF9,AG9,AI9,AJ9,AK9,AO9,AP9,AR9,AS9,AU9,AV9,AZ9,BA9,BC9,BD9,BE9,BH9,BL9,BM9,BQ9,BR9) -> 67.709953 | CB9: =AVERAGE(I9,X9,AE9,AH9,AQ9,AT9,AW9,BF9,BI9,BO9) -> 89.763342 | CC9: =AVERAGE(AC9,AL9) -> 68.996824 | CD9: =AVERAGE(Q9,AM9,BB9,BN9) -> 51.839794 | CF9: =AVERAGE(F9,AN9) -> 48.747193 | CG9: =AVERAGE(G9,M9,V9,Y9,AX9,BG9,BJ9,BP9,BS9) -> 44.797598 | CH9: =AVERAGE(AA9,AY9,BK9) -> 35.496463 | CJ9: =AVERAGE(C9,L9,O9,R9,AB9,AK9,AZ9,BC9,BL9,BR9) -> 68.607732 | CK9: =AVERAGE(D9,J9,P9,S9,AF9,AI9,AO9,AR9,AU9,BA9,BD9,BM9) -> 64.719077 | CL9: =AVERAGE(E9,H9,K9,N9,T9,W9,Z9,AD9,AG9,AJ9,AP9,AS9,AV9,BE9,BH9,BQ9) -> 74.098351 | CN9: =(BX9-$BV9)/$BV9*100 -> 19.256518 | CO9: =(BY9-$BV9)/$BV9*100 -> -34.054306 | CP9: =(BZ9-$BV9)/$BV9*100 -> 3.9413365 | CR9: =(CB9-$BV9)/$BV9*100 -> 37.795425 | CS9: =(CC9-$BV9)/$BV9*100 -> 5.9168089 | CT9: =(CD9-$BV9)/$BV9*100 -> -20.420894 | CV9: =(CF9-$BV9)/$BV9*100 -> -25.168337 | CW9: =(CG9-$BV9)/$BV9*100 -> -31.231348 | CX9: =(CH9-$BV9)/$BV9*100 -> -45.509491 | CZ9: =(CJ9-$BV9)/$BV9*100 -> 5.319515 | DA9: =(CK9-$BV9)/$BV9*100 -> -0.64994762 | DB9: =(CL9-$BV9)/$BV9*100 -> 13.748146 | DD9: =BX9 -> 77.68664 | DE9: =BY9 -> 42.958653 | DF9: =BZ9 -> 67.709953 | DH9: =(CB9-$DD9)/$DD9*100 -> 15.545403 | DI9: =(CC9-$DD9)/$DD9*100 -> -11.185728 | DJ9: =(CD9-$DD9)/$DD9*100 -> -33.270645 | DL9: =(CF9-$DE9)/$DE9*100 -> 13.474677 | DM9: =(CG9-$DE9)/$DE9*100 -> 4.2807307 | DN9: =(CH9-$DE9)/$DE9*100 -> -17.370634 | DP9: =(CJ9-$DF9)/$DF9*100 -> 1.3259195 | DQ9: =(CK9-$DF9)/$DF9*100 -> -4.4171879 | DR9: =(CL9-$DF9)/$DF9*100 -> 9.4349463
A10: ='data convert'!A10 -> Jul | B10: ='data convert'!B10 -> 129.09412 | C10: ='data convert'!C10 -> 85.4 | D10: ='data convert'!D10 -> 108.54375 | E10: ='data convert'!E10 -> 94.952941 | F10: ='data convert'!F10 -> 54.426667 | G10: ='data convert'!G10 -> 82.877778 | H10: ='data convert'!H10 -> 25.583333 | ... BS10: ='data convert'!BS10 -> 219.32 | BV10: =AVERAGE(B10:BS10) -> 86.101047 | BX10: =AVERAGE(I10,Q10,X10,AC10,AE10,AH10,AL10,AM10,AQ10,AT10,AW10,BB10,BF10,BI10,BN10,BO10) -> 104.86959 | BY10: =AVERAGE(B10,F10,G10,M10,V10,Y10,AA10,AN10,AX10,AY10,BG10,BJ10,BK10,BP10,BS10) -> 90.943992 | BZ10: =AVERAGE(C10,D10,E10,H10,K10,L10,N10,O10,P10,R10,S10,T10,U10,W10,Z10,AB10,AD10,AF10,AG10,AI10,AJ10,AK10,AO10,AP10,AR10,AS10,AU10,AV10,AZ10,BA10,BC10,BD10,BE10,BH10,BL10,BM10,BQ10,BR10) -> 77.858081 | CB10: =AVERAGE(I10,X10,AE10,AH10,AQ10,AT10,AW10,BF10,BI10,BO10) -> 110.94945 | CC10: =AVERAGE(AC10,AL10) -> 79.126723 | CD10: =AVERAGE(Q10,AM10,BB10,BN10) -> 102.54139 | CF10: =AVERAGE(F10,AN10) -> 112.78044 | CG10: =AVERAGE(G10,M10,V10,Y10,AX10,BG10,BJ10,BP10,BS10) -> 89.868765 | CH10: =AVERAGE(AA10,AY10,BK10) -> 66.895331 | CJ10: =AVERAGE(C10,L10,O10,R10,AB10,AK10,AZ10,BC10,BL10,BR10) -> 101.81479 | CK10: =AVERAGE(D10,J10,P10,S10,AF10,AI10,AO10,AR10,AU10,BA10,BD10,BM10) -> 69.074072 | CL10: =AVERAGE(E10,H10,K10,N10,T10,W10,Z10,AD10,AG10,AJ10,AP10,AS10,AV10,BE10,BH10,BQ10) -> 67.595051 | CN10: =(BX10-$BV10)/$BV10*100 -> 21.798279 | CO10: =(BY10-$BV10)/$BV10*100 -> 5.624722 | CP10: =(BZ10-$BV10)/$BV10*100 -> -9.5735958 | CR10: =(CB10-$BV10)/$BV10*100 -> 28.859579 | CS10: =(CC10-$BV10)/$BV10*100 -> -8.1001617 | CT10: =(CD10-$BV10)/$BV10*100 -> 19.094247 | CV10: =(CF10-$BV10)/$BV10*100 -> 30.986141 | CW10: =(CG10-$BV10)/$BV10*100 -> 4.375926 | CX10: =(CH10-$BV10)/$BV10*100 -> -22.306019 | CZ10: =(CJ10-$BV10)/$BV10*100 -> 18.250354 | DA10: =(CK10-$BV10)/$BV10*100 -> -19.775572 | DB10: =(CL10-$BV10)/$BV10*100 -> -21.493346 | DD10: =BX10 -> 104.86959 | DE10: =BY10 -> 90.943992 | DF10: =BZ10 -> 77.858081 | DH10: =(CB10-$DD10)/$DD10*100 -> 5.7975372 | DI10: =(CC10-$DD10)/$DD10*100 -> -24.547506 | DJ10: =(CD10-$DD10)/$DD10*100 -> -2.2200899 | DL10: =(CF10-$DE10)/$DE10*100 -> 24.010874 | DM10: =(CG10-$DE10)/$DE10*100 -> -1.1822953 | DN10: =(CH10-$DE10)/$DE10*100 -> -26.443375 | DP10: =(CJ10-$DF10)/$DF10*100 -> 30.769719 | DQ10: =(CK10-$DF10)/$DF10*100 -> -11.282077 | DR10: =(CL10-$DF10)/$DF10*100 -> -13.181714
A11: ='data convert'!A11 -> Aug | B11: ='data convert'!B11 -> 26.047059 | C11: ='data convert'!C11 -> 92.5 | D11: ='data convert'!D11 -> 21.05 | E11: ='data convert'!E11 -> 113.16471 | F11: ='data convert'!F11 -> 102.02 | G11: ='data convert'!G11 -> 57.783333 | H11: ='data convert'!H11 -> 34.333333 | ... BS11: ='data convert'!BS11 -> 89.51 | BV11: =AVERAGE(B11:BS11) -> 106.72904 | BX11: =AVERAGE(I11,Q11,X11,AC11,AE11,AH11,AL11,AM11,AQ11,AT11,AW11,BB11,BF11,BI11,BN11,BO11) -> 126.69536 | BY11: =AVERAGE(B11,F11,G11,M11,V11,Y11,AA11,AN11,AX11,AY11,BG11,BJ11,BK11,BP11,BS11) -> 124.48672 | BZ11: =AVERAGE(C11,D11,E11,H11,K11,L11,N11,O11,P11,R11,S11,T11,U11,W11,Z11,AB11,AD11,AF11,AG11,AI11,AJ11,AK11,AO11,AP11,AR11,AS11,AU11,AV11,AZ11,BA11,BC11,BD11,BE11,BH11,BL11,BM11,BQ11,BR11) -> 90.998666 | CB11: =AVERAGE(I11,X11,AE11,AH11,AQ11,AT11,AW11,BF11,BI11,BO11) -> 132.96249 | CC11: =AVERAGE(AC11,AL11) -> 79.439291 | CD11: =AVERAGE(Q11,AM11,BB11,BN11) -> 134.65558 | CF11: =AVERAGE(F11,AN11) -> 72.785 | CG11: =AVERAGE(G11,M11,V11,Y11,AX11,BG11,BJ11,BP11,BS11) -> 139.83564 | CH11: =AVERAGE(AA11,AY11,BK11) -> 145.721 | CJ11: =AVERAGE(C11,L11,O11,R11,AB11,AK11,AZ11,BC11,BL11,BR11) -> 77.351275 | CK11: =AVERAGE(D11,J11,P11,S11,AF11,AI11,AO11,AR11,AU11,BA11,BD11,BM11) -> 105.28428 | CL11: =AVERAGE(E11,H11,K11,N11,T11,W11,Z11,AD11,AG11,AJ11,AP11,AS11,AV11,BE11,BH11,BQ11) -> 91.072211 | CN11: =(BX11-$BV11)/$BV11*100 -> 18.707483 | CO11: =(BY11-$BV11)/$BV11*100 -> 16.638094 | CP11: =(BZ11-$BV11)/$BV11*100 -> -14.73861 | CR11: =(CB11-$BV11)/$BV11*100 -> 24.57948 | CS11: =(CC11-$BV11)/$BV11*100 -> -25.569191 | CT11: =(CD11-$BV11)/$BV11*100 -> 26.165826 | CV11: =(CF11-$BV11)/$BV11*100 -> -31.803943 | CW11: =(CG11-$BV11)/$BV11*100 -> 31.019298 | CX11: =(CH11-$BV11)/$BV11*100 -> 36.533591 | CZ11: =(CJ11-$BV11)/$BV11*100 -> -27.525562 | DA11: =(CK11-$BV11)/$BV11*100 -> -1.3536712 | DB11: =(CL11-$BV11)/$BV11*100 -> -14.669703 | DD11: =BX11 -> 126.69536 | DE11: =BY11 -> 124.48672 | DF11: =BZ11 -> 90.998666 | DH11: =(CB11-$DD11)/$DD11*100 -> 4.946611 | DI11: =(CC11-$DD11)/$DD11*100 -> -37.298975 | DJ11: =(CD11-$DD11)/$DD11*100 -> 6.2829598 | DL11: =(CF11-$DE11)/$DE11*100 -> -41.531917 | DM11: =(CG11-$DE11)/$DE11*100 -> 12.329766 | DN11: =(CH11-$DE11)/$DE11*100 -> 17.05746 | DP11: =(CJ11-$DF11)/$DF11*100 -> -14.997352 | DQ11: =(CK11-$DF11)/$DF11*100 -> 15.698711 | DR11: =(CL11-$DF11)/$DF11*100 -> 0.080819451
A12: ='data convert'!A12 -> Sep | B12: ='data convert'!B12 -> 147.94118 | C12: ='data convert'!C12 -> 126.075 | D12: ='data convert'!D12 -> 114.975 | E12: ='data convert'!E12 -> 17.7 | F12: ='data convert'!F12 -> 121.69333 | G12: ='data convert'!G12 -> 109.83889 | H12: ='data convert'!H12 -> 43.033333 | ... BS12: ='data convert'!BS12 -> 180.54 | BV12: =AVERAGE(B12:BS12) -> 159.77534 | BX12: =AVERAGE(I12,Q12,X12,AC12,AE12,AH12,AL12,AM12,AQ12,AT12,AW12,BB12,BF12,BI12,BN12,BO12) -> 161.11306 | BY12: =AVERAGE(B12,F12,G12,M12,V12,Y12,AA12,AN12,AX12,AY12,BG12,BJ12,BK12,BP12,BS12) -> 154.00822 | BZ12: =AVERAGE(C12,D12,E12,H12,K12,L12,N12,O12,P12,R12,S12,T12,U12,W12,Z12,AB12,AD12,AF12,AG12,AI12,AJ12,AK12,AO12,AP12,AR12,AS12,AU12,AV12,AZ12,BA12,BC12,BD12,BE12,BH12,BL12,BM12,BQ12,BR12) -> 159.47289 | CB12: =AVERAGE(I12,X12,AE12,AH12,AQ12,AT12,AW12,BF12,BI12,BO12) -> 144.08727 | CC12: =AVERAGE(AC12,AL12) -> 183.98274 | CD12: =AVERAGE(Q12,AM12,BB12,BN12) -> 192.24268 | CF12: =AVERAGE(F12,AN12) -> 152.65719 | CG12: =AVERAGE(G12,M12,V12,Y12,AX12,BG12,BJ12,BP12,BS12) -> 169.83683 | CH12: =AVERAGE(AA12,AY12,BK12) -> 109.44544 | CJ12: =AVERAGE(C12,L12,O12,R12,AB12,AK12,AZ12,BC12,BL12,BR12) -> 179.39252 | CK12: =AVERAGE(D12,J12,P12,S12,AF12,AI12,AO12,AR12,AU12,BA12,BD12,BM12) -> 171.26689 | CL12: =AVERAGE(E12,H12,K12,N12,T12,W12,Z12,AD12,AG12,AJ12,AP12,AS12,AV12,BE12,BH12,BQ12) -> 145.12896 | CN12: =(BX12-$BV12)/$BV12*100 -> 0.83725051 | CO12: =(BY12-$BV12)/$BV12*100 -> -3.6095132 | CP12: =(BZ12-$BV12)/$BV12*100 -> -0.1892943 | CR12: =(CB12-$BV12)/$BV12*100 -> -9.8188293 | CS12: =(CC12-$BV12)/$BV12*100 -> 15.1509 | CT12: =(CD12-$BV12)/$BV12*100 -> 20.320626 | CV12: =(CF12-$BV12)/$BV12*100 -> -4.4550949 | CW12: =(CG12-$BV12)/$BV12*100 -> 6.2972759 | CX12: =(CH12-$BV12)/$BV12*100 -> -31.500414 | CZ12: =(CJ12-$BV12)/$BV12*100 -> 12.27798 | DA12: =(CK12-$BV12)/$BV12*100 -> 7.1923198 | DB12: =(CL12-$BV12)/$BV12*100 -> -9.166855 | DD12: =BX12 -> 161.11306 | DE12: =BY12 -> 154.00822 | DF12: =BZ12 -> 159.47289 | DH12: =(CB12-$DD12)/$DD12*100 -> -10.567603 | DI12: =(CC12-$DD12)/$DD12*100 -> 14.194803 | DJ12: =(CD12-$DD12)/$DD12*100 -> 19.321605 | DL12: =(CF12-$DE12)/$DE12*100 -> -0.87724607 | DM12: =(CG12-$DE12)/$DE12*100 -> 10.277766 | DN12: =(CH12-$DE12)/$DE12*100 -> -28.935325 | DP12: =(CJ12-$DF12)/$DF12*100 -> 12.490919 | DQ12: =(CK12-$DF12)/$DF12*100 -> 7.3956136 | DR12: =(CL12-$DF12)/$DF12*100 -> -8.994587
A13: ='data convert'!A13 -> Oct | B13: ='data convert'!B13 -> 77.105882 | C13: ='data convert'!C13 -> 214.05 | D13: ='data convert'!D13 -> 295.4875 | E13: ='data convert'!E13 -> 167.42353 | F13: ='data convert'!F13 -> 143.62 | G13: ='data convert'!G13 -> 352.83889 | H13: ='data convert'!H13 -> 151.93889 | ... BS13: ='data convert'!BS13 -> 194.64 | BV13: =AVERAGE(B13:BS13) -> 154.04598 | BX13: =AVERAGE(I13,Q13,X13,AC13,AE13,AH13,AL13,AM13,AQ13,AT13,AW13,BB13,BF13,BI13,BN13,BO13) -> 125.09064 | BY13: =AVERAGE(B13,F13,G13,M13,V13,Y13,AA13,AN13,AX13,AY13,BG13,BJ13,BK13,BP13,BS13) -> 181.71328 | BZ13: =AVERAGE(C13,D13,E13,H13,K13,L13,N13,O13,P13,R13,S13,T13,U13,W13,Z13,AB13,AD13,AF13,AG13,AI13,AJ13,AK13,AO13,AP13,AR13,AS13,AU13,AV13,AZ13,BA13,BC13,BD13,BE13,BH13,BL13,BM13,BQ13,BR13) -> 158.46216 | CB13: =AVERAGE(I13,X13,AE13,AH13,AQ13,AT13,AW13,BF13,BI13,BO13) -> 127.84614 | CC13: =AVERAGE(AC13,AL13) -> 151.53757 | CD13: =AVERAGE(Q13,AM13,BB13,BN13) -> 104.97845 | CF13: =AVERAGE(F13,AN13) -> 132.56263 | CG13: =AVERAGE(G13,M13,V13,Y13,AX13,BG13,BJ13,BP13,BS13) -> 212.20629 | CH13: =AVERAGE(AA13,AY13,BK13) -> 157.87046 | CJ13: =AVERAGE(C13,L13,O13,R13,AB13,AK13,AZ13,BC13,BL13,BR13) -> 152.3983 | CK13: =AVERAGE(D13,J13,P13,S13,AF13,AI13,AO13,AR13,AU13,BA13,BD13,BM13) -> 160.57073 | CL13: =AVERAGE(E13,H13,K13,N13,T13,W13,Z13,AD13,AG13,AJ13,AP13,AS13,AV13,BE13,BH13,BQ13) -> 142.02829 | CN13: =(BX13-$BV13)/$BV13*100 -> -18.796555 | CO13: =(BY13-$BV13)/$BV13*100 -> 17.960416 | CP13: =(BZ13-$BV13)/$BV13*100 -> 2.8667919 | CR13: =(CB13-$BV13)/$BV13*100 -> -17.007807 | CS13: =(CC13-$BV13)/$BV13*100 -> -1.6283527 | CT13: =(CD13-$BV13)/$BV13*100 -> -31.852524 | CV13: =(CF13-$BV13)/$BV13*100 -> -13.946062 | CW13: =(CG13-$BV13)/$BV13*100 -> 37.755165 | CX13: =(CH13-$BV13)/$BV13*100 -> 2.4826867 | CZ13: =(CJ13-$BV13)/$BV13*100 -> -1.0696047 | DA13: =(CK13-$BV13)/$BV13*100 -> 4.2355896 | DB13: =(CL13-$BV13)/$BV13*100 -> -7.8013623 | DD13: =BX13 -> 125.09064 | DE13: =BY13 -> 181.71328 | DF13: =BZ13 -> 158.46216 | DH13: =(CB13-$DD13)/$DD13*100 -> 2.2027972 | DI13: =(CC13-$DD13)/$DD13*100 -> 21.142209 | DJ13: =(CD13-$DD13)/$DD13*100 -> -16.078097 | DL13: =(CF13-$DE13)/$DE13*100 -> -27.048462 | DM13: =(CG13-$DE13)/$DE13*100 -> 16.780841 | DN13: =(CH13-$DE13)/$DE13*100 -> -13.121121 | DP13: =(CJ13-$DF13)/$DF13*100 -> -3.8266932 | DQ13: =(CK13-$DF13)/$DF13*100 -> 1.3306507 | DR13: =(CL13-$DF13)/$DF13*100 -> -10.370844
A14: ='data convert'!A14 -> Nov | B14: ='data convert'!B14 -> 20.711765 | C14: ='data convert'!C14 -> 0 | D14: ='data convert'!D14 -> 1.8375 | E14: ='data convert'!E14 -> 0 | F14: ='data convert'!F14 -> 51.833333 | G14: ='data convert'!G14 -> 79.755556 | H14: ='data convert'!H14 -> 29.066667 | ... BS14: ='data convert'!BS14 -> 78.03 | BV14: =AVERAGE(B14:BS14) -> 49.116735 | BX14: =AVERAGE(I14,Q14,X14,AC14,AE14,AH14,AL14,AM14,AQ14,AT14,AW14,BB14,BF14,BI14,BN14,BO14) -> 66.332542 | BY14: =AVERAGE(B14,F14,G14,M14,V14,Y14,AA14,AN14,AX14,AY14,BG14,BJ14,BK14,BP14,BS14) -> 43.099141 | BZ14: =AVERAGE(C14,D14,E14,H14,K14,L14,N14,O14,P14,R14,S14,T14,U14,W14,Z14,AB14,AD14,AF14,AG14,AI14,AJ14,AK14,AO14,AP14,AR14,AS14,AU14,AV14,AZ14,BA14,BC14,BD14,BE14,BH14,BL14,BM14,BQ14,BR14) -> 45.168781 | CB14: =AVERAGE(I14,X14,AE14,AH14,AQ14,AT14,AW14,BF14,BI14,BO14) -> 48.807428 | CC14: =AVERAGE(AC14,AL14) -> 72.481655 | CD14: =AVERAGE(Q14,AM14,BB14,BN14) -> 107.07077 | CF14: =AVERAGE(F14,AN14) -> 29.437719 | CG14: =AVERAGE(G14,M14,V14,Y14,AX14,BG14,BJ14,BP14,BS14) -> 37.549037 | CH14: =AVERAGE(AA14,AY14,BK14) -> 76.319525 | CJ14: =AVERAGE(C14,L14,O14,R14,AB14,AK14,AZ14,BC14,BL14,BR14) -> 50.357293 | CK14: =AVERAGE(D14,J14,P14,S14,AF14,AI14,AO14,AR14,AU14,BA14,BD14,BM14) -> 28.534952 | CL14: =AVERAGE(E14,H14,K14,N14,T14,W14,Z14,AD14,AG14,AJ14,AP14,AS14,AV14,BE14,BH14,BQ14) -> 53.836188 | CN14: =(BX14-$BV14)/$BV14*100 -> 35.050797 | CO14: =(BY14-$BV14)/$BV14*100 -> -12.251617 | CP14: =(BZ14-$BV14)/$BV14*100 -> -8.0379005 | CR14: =(CB14-$BV14)/$BV14*100 -> -0.62973918 | CS14: =(CC14-$BV14)/$BV14*100 -> 47.570182 | CT14: =(CD14-$BV14)/$BV14*100 -> 117.99244 | CV14: =(CF14-$BV14)/$BV14*100 -> -40.065806 | CW14: =(CG14-$BV14)/$BV14*100 -> -23.551439 | CX14: =(CH14-$BV14)/$BV14*100 -> 55.383953 | CZ14: =(CJ14-$BV14)/$BV14*100 -> 2.5257344 | DA14: =(CK14-$BV14)/$BV14*100 -> -41.90381 | DB14: =(CL14-$BV14)/$BV14*100 -> 9.6086455 | DD14: =BX14 -> 66.332542 | DE14: =BY14 -> 43.099141 | DF14: =BZ14 -> 45.168781 | DH14: =(CB14-$DD14)/$DD14*100 -> -26.420086 | DI14: =(CC14-$DD14)/$DD14*100 -> 9.2701307 | DJ14: =(CD14-$DD14)/$DD14*100 -> 61.415149 | DL14: =(CF14-$DE14)/$DE14*100 -> -31.697665 | DM14: =(CG14-$DE14)/$DE14*100 -> -12.877528 | DN14: =(CH14-$DE14)/$DE14*100 -> 77.078994 | DP14: =(CJ14-$DF14)/$DF14*100 -> 11.486944 | DQ14: =(CK14-$DF14)/$DF14*100 -> -36.825942 | DR14: =(CL14-$DF14)/$DF14*100 -> 19.188933
